Workbook

Sheet SALES
A1: Column1 | B1: Date | C1: Transaction type | D1: Number | E1: Customer full name | F1: Memo/Description | G1: Quantity | H1: Sales price | I1: Amount | J1: Balance | K1: Line
A2: 128 DICHONDRA LAWN | K2: {=_xlfn.LET(_xlpm.d,UPPER(TRIM(CLEAN(SUBSTITUTE(F2,CHAR(160)," ")))),_xlpm.keys,UPPER(TRIM(MAP!$B$2:$B$1000)),_xlpm.vals,MAP!$A$2:$A$1000,_xlpm.matchlen,IF(ISNUMBER(SEARCH(_xlpm.keys,_xlpm.d)),LEN(_xlpm.keys),0),_xlpm.best,MAX(_xlpm.matchlen),IF(_xlpm.best=0,"",INDEX(_xlpm.vals,MATCH(_xlpm.best,_xlpm.matchlen,0))))}
B3: 45670 | C3: Invoice | D3: 86225 | E3: LITTLE AUSTRIA | F3: 128 DICHONDRA LAWN | G3: 2 | H3: 117.3 | I3: 234.6 | J3: 234.6 | K3: {=_xlfn.LET(_xlpm.d,UPPER(TRIM(CLEAN(SUBSTITUTE(F3,CHAR(160)," ")))),_xlpm.keys,UPPER(TRIM(MAP!$B$2:$B$1000)),_xlpm.vals,MAP!$A$2:$A$1000,_xlpm.matchlen,IF(ISNUMBER(SEARCH(_xlpm.keys,_xlpm.d)),LEN(_xlpm.keys),0),_xlpm.best,MAX(_xlpm.matchlen),IF(_xlpm.best=0,"",INDEX(_xlpm.vals,MATCH(_xlpm.best,_xlpm.matchlen,0))))} -> LAWN PLUGS
B4: 45679 | C4: Invoice | D4: 86273 | E4: LITTLE AUSTRIA | F4: 128 DICHONDRA LAWN | G4: 2 | H4: 117.3 | I4: 234.6 | J4: 469.2 | K4: {=_xlfn.LET(_xlpm.d,UPPER(TRIM(CLEAN(SUBSTITUTE(F4,CHAR(160)," ")))),_xlpm.keys,UPPER(TRIM(MAP!$B$2:$B$1000)),_xlpm.vals,MAP!$A$2:$A$1000,_xlpm.matchlen,IF(ISNUMBER(SEARCH(_xlpm.keys,_xlpm.d)),LEN(_xlpm.keys),0),_xlpm.best,MAX(_xlpm.matchlen),IF(_xlpm.best=0,"",INDEX(_xlpm.vals,MATCH(_xlpm.best,_xlpm.matchlen,0))))} -> LAWN PLUGS
B5: 45685 | C5: Invoice | D5: 86329 | E5: CENTRAL NURSERY DEPOT | F5: 128 DICHONDRA LAWN | G5: 25 | H5: 117.3 | I5: 2932.5 | J5: 3401.7 | K5: {=_xlfn.LET(_xlpm.d,UPPER(TRIM(CLEAN(SUBSTITUTE(F5,CHAR(160)," ")))),_xlpm.keys,UPPER(TRIM(MAP!$B$2:$B$1000)),_xlpm.vals,MAP!$A$2:$A$1000,_xlpm.matchlen,IF(ISNUMBER(SEARCH(_xlpm.keys,_xlpm.d)),LEN(_xlpm.keys),0),_xlpm.best,MAX(_xlpm.matchlen),IF(_xlpm.best=0,"",INDEX(_xlpm.vals,MATCH(_xlpm.best,_xlpm.matchlen,0))))} -> LAWN PLUGS
B6: 45688 | C6: Invoice | D6: 86376 | E6: CENTRAL NURSERY DEPOT | F6: 128 DICHONDRA LAWN | G6: 25 | H6: 117.3 | I6: 2932.5 | J6: 6334.2 | K6: {=_xlfn.LET(_xlpm.d,UPPER(TRIM(CLEAN(SUBSTITUTE(F6,CHAR(160)," ")))),_xlpm.keys,UPPER(TRIM(MAP!$B$2:$B$1000)),_xlpm.vals,MAP!$A$2:$A$1000,_xlpm.matchlen,IF(ISNUMBER(SEARCH(_xlpm.keys,_xlpm.d)),LEN(_xlpm.keys),0),_xlpm.best,MAX(_xlpm.matchlen),IF(_xlpm.best=0,"",INDEX(_xlpm.vals,MATCH(_xlpm.best,_xlpm.matchlen,0))))} -> LAWN PLUGS
B7: 45695 | C7: Invoice | D7: 86451 | E7: NINFA GARDEN CENTRE | F7: 128 DICHONDRA LAWN | G7: 5 | H7: 118.8 | I7: 594 | J7: 6928.2 | K7: {=_xlfn.LET(_xlpm.d,UPPER(TRIM(CLEAN(SUBSTITUTE(F7,CHAR(160)," ")))),_xlpm.keys,UPPER(TRIM(MAP!$B$2:$B$1000)),_xlpm.vals,MAP!$A$2:$A$1000,_xlpm.matchlen,IF(ISNUMBER(SEARCH(_xlpm.keys,_xlpm.d)),LEN(_xlpm.keys),0),_xlpm.best,MAX(_xlpm.matchlen),IF(_xlpm.best=0,"",INDEX(_xlpm.vals,MATCH(_xlpm.best,_xlpm.matchlen,0))))} -> LAWN PLUGS
B8: 45763 | C8: Invoice | D8: 87097 | E8: LITTLE AUSTRIA | F8: 128 DICHONDRA LAWN | G8: 4 | H8: 117.3 | I8: 469.2 | J8: 7397.4 | K8: {=_xlfn.LET(_xlpm.d,UPPER(TRIM(CLEAN(SUBSTITUTE(F8,CHAR(160)," ")))),_xlpm.keys,UPPER(TRIM(MAP!$B$2:$B$1000)),_xlpm.vals,MAP!$A$2:$A$1000,_xlpm.matchlen,IF(ISNUMBER(SEARCH(_xlpm.keys,_xlpm.d)),LEN(_xlpm.keys),0),_xlpm.best,MAX(_xlpm.matchlen),IF(_xlpm.best=0,"",INDEX(_xlpm.vals,MATCH(_xlpm.best,_xlpm.matchlen,0))))} -> LAWN PLUGS
B9: 45800 | C9: Invoice | D9: 87400 | E9: FOUR SEASONS | F9: 128 DICHONDRA LAWN | G9: 3 | H9: 117.3 | I9: 351.9 | J9: 7749.3 | K9: {=_xlfn.LET(_xlpm.d,UPPER(TRIM(CLEAN(SUBSTITUTE(F9,CHAR(160)," ")))),_xlpm.keys,UPPER(TRIM(MAP!$B$2:$B$1000)),_xlpm.vals,MAP!$A$2:$A$1000,_xlpm.matchlen,IF(ISNUMBER(SEARCH(_xlpm.keys,_xlpm.d)),LEN(_xlpm.keys),0),_xlpm.best,MAX(_xlpm.matchlen),IF(_xlpm.best=0,"",INDEX(_xlpm.vals,MATCH(_xlpm.best,_xlpm.matchlen,0))))} -> LAWN PLUGS
B10: 46042 | C10: Invoice | D10: 89923 | E10: JOY GARDENS | F10: 128 DICHONDRA LAWN | G10: 5 | H10: 124.3 | I10: 621.5 | J10: 8370.8 | K10: {=_xlfn.LET(_xlpm.d,UPPER(TRIM(CLEAN(SUBSTITUTE(F10,CHAR(160)," ")))),_xlpm.keys,UPPER(TRIM(MAP!$B$2:$B$1000)),_xlpm.vals,MAP!$A$2:$A$1000,_xlpm.matchlen,IF(ISNUMBER(SEARCH(_xlpm.keys,_xlpm.d)),LEN(_xlpm.keys),0),_xlpm.best,MAX(_xlpm.matchlen),IF(_xlpm.best=0,"",INDEX(_xlpm.vals,MATCH(_xlpm.best,_xlpm.matchlen,0))))} -> LAWN PLUGS
B11: 46044 | C11: Invoice | D11: 89959 | E11: GARDENSHOP PARKTOWN | F11: 128 DICHONDRA LAWN | G11: 5 | H11: 124.3 | I11: 621.5 | J11: 8992.3 | K11: {=_xlfn.LET(_xlpm.d,UPPER(TRIM(CLEAN(SUBSTITUTE(F11,CHAR(160)," ")))),_xlpm.keys,UPPER(TRIM(MAP!$B$2:$B$1000)),_xlpm.vals,MAP!$A$2:$A$1000,_xlpm.matchlen,IF(ISNUMBER(SEARCH(_xlpm.keys,_xlpm.d)),LEN(_xlpm.keys),0),_xlpm.best,MAX(_xlpm.matchlen),IF(_xlpm.best=0,"",INDEX(_xlpm.vals,MATCH(_xlpm.best,_xlpm.matchlen,0))))} -> LAWN PLUGS
B12: 46051 | C12: Invoice | D12: 90028 | E12: CENTRAL NURSERY DEPOT | F12: 128 DICHONDRA LAWN | G12: 39 | H12: 124.3 | I12: 4847.7 | J12: 13840 | K12: {=_xlfn.LET(_xlpm.d,UPPER(TRIM(CLEAN(SUBSTITUTE(F12,CHAR(160)," ")))),_xlpm.keys,UPPER(TRIM(MAP!$B$2:$B$1000)),_xlpm.vals,MAP!$A$2:$A$1000,_xlpm.matchlen,IF(ISNUMBER(SEARCH(_xlpm.keys,_xlpm.d)),LEN(_xlpm.keys),0),_xlpm.best,MAX(_xlpm.matchlen),IF(_xlpm.best=0,"",INDEX(_xlpm.vals,MATCH(_xlpm.best,_xlpm.matchlen,0))))} -> LAWN PLUGS
B13: 46052 | C13: Invoice | D13: 90040 | E13: CENTRAL NURSERY DEPOT | F13: 128 DICHONDRA LAWN | G13: 5 | H13: 124.3 | I13: 621.5 | J13: 14461.5 | K13: {=_xlfn.LET(_xlpm.d,UPPER(TRIM(CLEAN(SUBSTITUTE(F13,CHAR(160)," ")))),_xlpm.keys,UPPER(TRIM(MAP!$B$2:$B$1000)),_xlpm.vals,MAP!$A$2:$A$1000,_xlpm.matchlen,IF(ISNUMBER(SEARCH(_xlpm.keys,_xlpm.d)),LEN(_xlpm.keys),0),_xlpm.best,MAX(_xlpm.matchlen),IF(_xlpm.best=0,"",INDEX(_xlpm.vals,MATCH(_xlpm.best,_xlpm.matchlen,0))))} -> LAWN PLUGS
B14: 46104 | C14: Invoice | D14: 90511 | E14: PRINCESS GROOT BOME | F14: 128 DICHONDRA LAWN | G14: 6 | H14: 124.3 | I14: 745.8 | J14: 15207.3 | K14: {=_xlfn.LET(_xlpm.d,UPPER(TRIM(CLEAN(SUBSTITUTE(F14,CHAR(160)," ")))),_xlpm.keys,UPPER(TRIM(MAP!$B$2:$B$1000)),_xlpm.vals,MAP!$A$2:$A$1000,_xlpm.matchlen,IF(ISNUMBER(SEARCH(_xlpm.keys,_xlpm.d)),LEN(_xlpm.keys),0),_xlpm.best,MAX(_xlpm.matchlen),IF(_xlpm.best=0,"",INDEX(_xlpm.vals,MATCH(_xlpm.best,_xlpm.matchlen,0))))} -> LAWN PLUGS
A15: Total for 128 DICHONDRA LAWN | G15: 126 | I15: =I3+I4+I5+I6+I7+I8+I9+I10+I11+I12+I13+I14 -> 15207.3 | K15: {=_xlfn.LET(_xlpm.d,UPPER(TRIM(CLEAN(SUBSTITUTE(F15,CHAR(160)," ")))),_xlpm.keys,UPPER(TRIM(MAP!$B$2:$B$1000)),_xlpm.vals,MAP!$A$2:$A$1000,_xlpm.matchlen,IF(ISNUMBER(SEARCH(_xlpm.keys,_xlpm.d)),LEN(_xlpm.keys),0),_xlpm.best,MAX(_xlpm.matchlen),IF(_xlpm.best=0,"",INDEX(_xlpm.vals,MATCH(_xlpm.best,_xlpm.matchlen,0))))}
A16: 128 LM LAWN | K16: {=_xlfn.LET(_xlpm.d,UPPER(TRIM(CLEAN(SUBSTITUTE(F16,CHAR(160)," ")))),_xlpm.keys,UPPER(TRIM(MAP!$B$2:$B$1000)),_xlpm.vals,MAP!$A$2:$A$1000,_xlpm.matchlen,IF(ISNUMBER(SEARCH(_xlpm.keys,_xlpm.d)),LEN(_xlpm.keys),0),_xlpm.best,MAX(_xlpm.matchlen),IF(_xlpm.best=0,"",INDEX(_xlpm.vals,MATCH(_xlpm.best,_xlpm.matchlen,0))))}
B17: 45671 | C17: Invoice | D17: 86176 | E17: NINFA GARDEN CENTRE | F17: 128 LM LAWN | G17: 4 | H17: 117.3 | I17: 469.2 | J17: 469.2 | K17: {=_xlfn.LET(_xlpm.d,UPPER(TRIM(CLEAN(SUBSTITUTE(F17,CHAR(160)," ")))),_xlpm.keys,UPPER(TRIM(MAP!$B$2:$B$1000)),_xlpm.vals,MAP!$A$2:$A$1000,_xlpm.matchlen,IF(ISNUMBER(SEARCH(_xlpm.keys,_xlpm.d)),LEN(_xlpm.keys),0),_xlpm.best,MAX(_xlpm.matchlen),IF(_xlpm.best=0,"",INDEX(_xlpm.vals,MATCH(_xlpm.best,_xlpm.matchlen,0))))} -> LAWN PLUGS
B18: 45674 | C18: Invoice | D18: 86223 | E18: HABITITNAK/KEENGRO | F18: 128 LM LAWN | G18: 5 | H18: 117.3 | I18: 586.5 | J18: 1055.7 | K18: {=_xlfn.LET(_xlpm.d,UPPER(TRIM(CLEAN(SUBSTITUTE(F18,CHAR(160)," ")))),_xlpm.keys,UPPER(TRIM(MAP!$B$2:$B$1000)),_xlpm.vals,MAP!$A$2:$A$1000,_xlpm.matchlen,IF(ISNUMBER(SEARCH(_xlpm.keys,_xlpm.d)),LEN(_xlpm.keys),0),_xlpm.best,MAX(_xlpm.matchlen),IF(_xlpm.best=0,"",INDEX(_xlpm.vals,MATCH(_xlpm.best,_xlpm.matchlen,0))))} -> LAWN PLUGS
B19: 45680 | C19: Invoice | D19: 86333 | E19: NYLIES KWEKERY | F19: 128 LM LAWN | G19: 10 | H19: 117.3 | I19: 1173 | J19: 2228.7 | K19: {=_xlfn.LET(_xlpm.d,UPPER(TRIM(CLEAN(SUBSTITUTE(F19,CHAR(160)," ")))),_xlpm.keys,UPPER(TRIM(MAP!$B$2:$B$1000)),_xlpm.vals,MAP!$A$2:$A$1000,_xlpm.matchlen,IF(ISNUMBER(SEARCH(_xlpm.keys,_xlpm.d)),LEN(_xlpm.keys),0),_xlpm.best,MAX(_xlpm.matchlen),IF(_xlpm.best=0,"",INDEX(_xlpm.vals,MATCH(_xlpm.best,_xlpm.matchlen,0))))} -> LAWN PLUGS
B20: 45681 | C20: Invoice | D20: 86303 | E20: GARDENSHOP PARKTOWN | F20: 128 LM LAWN | G20: 10 | H20: 117.3 | I20: 1173 | J20: 3401.7 | K20: {=_xlfn.LET(_xlpm.d,UPPER(TRIM(CLEAN(SUBSTITUTE(F20,CHAR(160)," ")))),_xlpm.keys,UPPER(TRIM(MAP!$B$2:$B$1000)),_xlpm.vals,MAP!$A$2:$A$1000,_xlpm.matchlen,IF(ISNUMBER(SEARCH(_xlpm.keys,_xlpm.d)),LEN(_xlpm.keys),0),_xlpm.best,MAX(_xlpm.matchlen),IF(_xlpm.best=0,"",INDEX(_xlpm.vals,MATCH(_xlpm.best,_xlpm.matchlen,0))))} -> LAWN PLUGS
B21: 45686 | C21: Invoice | D21: 86352 | E21: JOY GARDENS | F21: 128 LM LAWN | G21: 5 | H21: 117.3 | I21: 586.5 | J21: 3988.2 | K21: {=_xlfn.LET(_xlpm.d,UPPER(TRIM(CLEAN(SUBSTITUTE(F21,CHAR(160)," ")))),_xlpm.keys,UPPER(TRIM(MAP!$B$2:$B$1000)),_xlpm.vals,MAP!$A$2:$A$1000,_xlpm.matchlen,IF(ISNUMBER(SEARCH(_xlpm.keys,_xlpm.d)),LEN(_xlpm.keys),0),_xlpm.best,MAX(_xlpm.matchlen),IF(_xlpm.best=0,"",INDEX(_xlpm.vals,MATCH(_xlpm.best,_xlpm.matchlen,0))))} -> LAWN PLUGS
B22: 45688 | C22: Invoice | D22: 86378 | E22: THREE LEAVES NURSERY | F22: 128 LM LAWN | G22: 3 | H22: 117.3 | I22: 351.9 | J22: 4340.1 | K22: {=_xlfn.LET(_xlpm.d,UPPER(TRIM(CLEAN(SUBSTITUTE(F22,CHAR(160)," ")))),_xlpm.keys,UPPER(TRIM(MAP!$B$2:$B$1000)),_xlpm.vals,MAP!$A$2:$A$1000,_xlpm.matchlen,IF(ISNUMBER(SEARCH(_xlpm.keys,_xlpm.d)),LEN(_xlpm.keys),0),_xlpm.best,MAX(_xlpm.matchlen),IF(_xlpm.best=0,"",INDEX(_xlpm.vals,MATCH(_xlpm.best,_xlpm.matchlen,0))))} -> LAWN PLUGS
B23: 45692 | C23: Invoice | D23: 86397 | E23: GARDENSHOP PARKTOWN | F23: 128 LM LAWN | G23: 8 | H23: 117.3 | I23: 938.4 | J23: 5278.5 | K23: {=_xlfn.LET(_xlpm.d,UPPER(TRIM(CLEAN(SUBSTITUTE(F23,CHAR(160)," ")))),_xlpm.keys,UPPER(TRIM(MAP!$B$2:$B$1000)),_xlpm.vals,MAP!$A$2:$A$1000,_xlpm.matchlen,IF(ISNUMBER(SEARCH(_xlpm.keys,_xlpm.d)),LEN(_xlpm.keys),0),_xlpm.best,MAX(_xlpm.matchlen),IF(_xlpm.best=0,"",INDEX(_xlpm.vals,MATCH(_xlpm.best,_xlpm.matchlen,0))))} -> LAWN PLUGS
B24: 45695 | C24: Invoice | D24: 86438 | E24: JOY GARDENS | F24: 128 LM LAWN | G24: 5 | H24: 117.3 | I24: 586.5 | J24: 5865 | K24: {=_xlfn.LET(_xlpm.d,UPPER(TRIM(CLEAN(SUBSTITUTE(F24,CHAR(160)," ")))),_xlpm.keys,UPPER(TRIM(MAP!$B$2:$B$1000)),_xlpm.vals,MAP!$A$2:$A$1000,_xlpm.matchlen,IF(ISNUMBER(SEARCH(_xlpm.keys,_xlpm.d)),LEN(_xlpm.keys),0),_xlpm.best,MAX(_xlpm.matchlen),IF(_xlpm.best=0,"",INDEX(_xlpm.vals,MATCH(_xlpm.best,_xlpm.matchlen,0))))} -> LAWN PLUGS
B25: 45695 | C25: Invoice | D25: 86451 | E25: NINFA GARDEN CENTRE | F25: 128 LM LAWN | G25: 15 | H25: 118.8 | I25: 1782 | J25: 7647 | K25: {=_xlfn.LET(_xlpm.d,UPPER(TRIM(CLEAN(SUBSTITUTE(F25,CHAR(160)," ")))),_xlpm.keys,UPPER(TRIM(MAP!$B$2:$B$1000)),_xlpm.vals,MAP!$A$2:$A$1000,_xlpm.matchlen,IF(ISNUMBER(SEARCH(_xlpm.keys,_xlpm.d)),LEN(_xlpm.keys),0),_xlpm.best,MAX(_xlpm.matchlen),IF(_xlpm.best=0,"",INDEX(_xlpm.vals,MATCH(_xlpm.best,_xlpm.matchlen,0))))} -> LAWN PLUGS
B26: 45700 | C26: Invoice | D26: 86497 | E26: DIE BLOMWINKELTJIE | F26: 128 LM LAWN | G26: 5 | H26: 117.3 | I26: 586.5 | J26: 8233.5 | K26: {=_xlfn.LET(_xlpm.d,UPPER(TRIM(CLEAN(SUBSTITUTE(F26,CHAR(160)," ")))),_xlpm.keys,UPPER(TRIM(MAP!$B$2:$B$1000)),_xlpm.vals,MAP!$A$2:$A$1000,_xlpm.matchlen,IF(ISNUMBER(SEARCH(_xlpm.keys,_xlpm.d)),LEN(_xlpm.keys),0),_xlpm.best,MAX(_xlpm.matchlen),IF(_xlpm.best=0,"",INDEX(_xlpm.vals,MATCH(_xlpm.best,_xlpm.matchlen,0))))} -> LAWN PLUGS
B27: 45709 | C27: Invoice | D27: 86587 | E27: JOY GARDENS | F27: 128 LM LAWN | G27: 13 | H27: 117.3 | I27: 1524.9 | J27: 9758.4 | K27: {=_xlfn.LET(_xlpm.d,UPPER(TRIM(CLEAN(SUBSTITUTE(F27,CHAR(160)," ")))),_xlpm.keys,UPPER(TRIM(MAP!$B$2:$B$1000)),_xlpm.vals,MAP!$A$2:$A$1000,_xlpm.matchlen,IF(ISNUMBER(SEARCH(_xlpm.keys,_xlpm.d)),LEN(_xlpm.keys),0),_xlpm.best,MAX(_xlpm.matchlen),IF(_xlpm.best=0,"",INDEX(_xlpm.vals,MATCH(_xlpm.best,_xlpm.matchlen,0))))} -> LAWN PLUGS
B28: 45709 | C28: Invoice | D28: 86589 | E28: OLIVE GARDENS | F28: 128 LM LAWN | G28: 7 | H28: 117.3 | I28: 821.1 | J28: 10579.5 | K28: {=_xlfn.LET(_xlpm.d,UPPER(TRIM(CLEAN(SUBSTITUTE(F28,CHAR(160)," ")))),_xlpm.keys,UPPER(TRIM(MAP!$B$2:$B$1000)),_xlpm.vals,MAP!$A$2:$A$1000,_xlpm.matchlen,IF(ISNUMBER(SEARCH(_xlpm.keys,_xlpm.d)),LEN(_xlpm.keys),0),_xlpm.best,MAX(_xlpm.matchlen),IF(_xlpm.best=0,"",INDEX(_xlpm.vals,MATCH(_xlpm.best,_xlpm.matchlen,0))))} -> LAWN PLUGS
... B51: 46073 | C51: Invoice | D51: 90252 | E51: NYLIES KWEKERY | F51: 128 LM LAWN | G51: 10 | H51: 126.35 | I51: 1263.5 | J51: 36318 | K51: {=_xlfn.LET(_xlpm.d,UPPER(TRIM(CLEAN(SUBSTITUTE(F51,CHAR(160)," ")))),_xlpm.keys,UPPER(TRIM(MAP!$B$2:$B$1000)),_xlpm.vals,MAP!$A$2:$A$1000,_xlpm.matchlen,IF(ISNUMBER(SEARCH(_xlpm.keys,_xlpm.d)),LEN(_xlpm.keys),0),_xlpm.best,MAX(_xlpm.matchlen),IF(_xlpm.best=0,"",INDEX(_xlpm.vals,MATCH(_xlpm.best,_xlpm.matchlen,0))))} -> LAWN PLUGS
A52: Total for 128 LM LAWN | G52: 308 | I52: =I17+I18+I19+I20+I21+I22+I23+I24+I25+I26+I27+I28+I29+I30+I31+I32+I33+I34+I35+I36+I37+I38+I39+I40+I41+I42+I43+I44+I45+I46+I47+I48+I49+I50+I51 -> 36318 | K52: {=_xlfn.LET(_xlpm.d,UPPER(TRIM(CLEAN(SUBSTITUTE(F52,CHAR(160)," ")))),_xlpm.keys,UPPER(TRIM(MAP!$B$2:$B$1000)),_xlpm.vals,MAP!$A$2:$A$1000,_xlpm.matchlen,IF(ISNUMBER(SEARCH(_xlpm.keys,_xlpm.d)),LEN(_xlpm.keys),0),_xlpm.best,MAX(_xlpm.matchlen),IF(_xlpm.best=0,"",INDEX(_xlpm.vals,MATCH(_xlpm.best,_xlpm.matchlen,0))))}
A53: 128 WONDER LAWN | K53: {=_xlfn.LET(_xlpm.d,UPPER(TRIM(CLEAN(SUBSTITUTE(F53,CHAR(160)," ")))),_xlpm.keys,UPPER(TRIM(MAP!$B$2:$B$1000)),_xlpm.vals,MAP!$A$2:$A$1000,_xlpm.matchlen,IF(ISNUMBER(SEARCH(_xlpm.keys,_xlpm.d)),LEN(_xlpm.keys),0),_xlpm.best,MAX(_xlpm.matchlen),IF(_xlpm.best=0,"",INDEX(_xlpm.vals,MATCH(_xlpm.best,_xlpm.matchlen,0))))}
B54: 46058 | C54: Invoice | D54: 90084 | E54: CENTRAL NURSERY DEPOT | F54: 128 WONDER LAWN | G54: 30 | H54: 124.3 | I54: 3729 | J54: 3729 | K54: {=_xlfn.LET(_xlpm.d,UPPER(TRIM(CLEAN(SUBSTITUTE(F54,CHAR(160)," ")))),_xlpm.keys,UPPER(TRIM(MAP!$B$2:$B$1000)),_xlpm.vals,MAP!$A$2:$A$1000,_xlpm.matchlen,IF(ISNUMBER(SEARCH(_xlpm.keys,_xlpm.d)),LEN(_xlpm.keys),0),_xlpm.best,MAX(_xlpm.matchlen),IF(_xlpm.best=0,"",INDEX(_xlpm.vals,MATCH(_xlpm.best,_xlpm.matchlen,0))))} -> LAWN PLUGS
B55: 46094 | C55: Invoice | D55: 90444 | E55: CASH SALE | F55: 128 WONDER LAWN | G55: 7 | H55: 124.3 | I55: 870.1 | J55: 4599.1 | K55: {=_xlfn.LET(_xlpm.d,UPPER(TRIM(CLEAN(SUBSTITUTE(F55,CHAR(160)," ")))),_xlpm.keys,UPPER(TRIM(MAP!$B$2:$B$1000)),_xlpm.vals,MAP!$A$2:$A$1000,_xlpm.matchlen,IF(ISNUMBER(SEARCH(_xlpm.keys,_xlpm.d)),LEN(_xlpm.keys),0),_xlpm.best,MAX(_xlpm.matchlen),IF(_xlpm.best=0,"",INDEX(_xlpm.vals,MATCH(_xlpm.best,_xlpm.matchlen,0))))} -> LAWN PLUGS
B56: 46099 | C56: Invoice | D56: 90490 | E56: GARDENSHOP PARKTOWN | F56: 128 WONDER LAWN | G56: 5 | H56: 124.3 | I56: 621.5 | J56: 5220.6 | K56: {=_xlfn.LET(_xlpm.d,UPPER(TRIM(CLEAN(SUBSTITUTE(F56,CHAR(160)," ")))),_xlpm.keys,UPPER(TRIM(MAP!$B$2:$B$1000)),_xlpm.vals,MAP!$A$2:$A$1000,_xlpm.matchlen,IF(ISNUMBER(SEARCH(_xlpm.keys,_xlpm.d)),LEN(_xlpm.keys),0),_xlpm.best,MAX(_xlpm.matchlen),IF(_xlpm.best=0,"",INDEX(_xlpm.vals,MATCH(_xlpm.best,_xlpm.matchlen,0))))} -> LAWN PLUGS
A57: Total for 128 WONDER LAWN | G57: 42 | I57: =I54+I55+I56 -> 5220.6 | K57: {=_xlfn.LET(_xlpm.d,UPPER(TRIM(CLEAN(SUBSTITUTE(F57,CHAR(160)," ")))),_xlpm.keys,UPPER(TRIM(MAP!$B$2:$B$1000)),_xlpm.vals,MAP!$A$2:$A$1000,_xlpm.matchlen,IF(ISNUMBER(SEARCH(_xlpm.keys,_xlpm.d)),LEN(_xlpm.keys),0),_xlpm.best,MAX(_xlpm.matchlen),IF(_xlpm.best=0,"",INDEX(_xlpm.vals,MATCH(_xlpm.best,_xlpm.matchlen,0))))}
A58: AT LAWN PLUG SEEDLINGS 128 | K58: {=_xlfn.LET(_xlpm.d,UPPER(TRIM(CLEAN(SUBSTITUTE(F58,CHAR(160)," ")))),_xlpm.keys,UPPER(TRIM(MAP!$B$2:$B$1000)),_xlpm.vals,MAP!$A$2:$A$1000,_xlpm.matchlen,IF(ISNUMBER(SEARCH(_xlpm.keys,_xlpm.d)),LEN(_xlpm.keys),0),_xlpm.best,MAX(_xlpm.matchlen),IF(_xlpm.best=0,"",INDEX(_xlpm.vals,MATCH(_xlpm.best,_xlpm.matchlen,0))))}
B59: 46000 | C59: Invoice | D59: 89548 | E59: BUILDERS WAREHOUSE:RIVONIA | F59: AT LAWN PLUG SEEDLINGS 128 | G59: 5 | H59: 126.35 | I59: 631.75 | J59: 631.75 | K59: {=_xlfn.LET(_xlpm.d,UPPER(TRIM(CLEAN(SUBSTITUTE(F59,CHAR(160)," ")))),_xlpm.keys,UPPER(TRIM(MAP!$B$2:$B$1000)),_xlpm.vals,MAP!$A$2:$A$1000,_xlpm.matchlen,IF(ISNUMBER(SEARCH(_xlpm.keys,_xlpm.d)),LEN(_xlpm.keys),0),_xlpm.best,MAX(_xlpm.matchlen),IF(_xlpm.best=0,"",INDEX(_xlpm.vals,MATCH(_xlpm.best,_xlpm.matchlen,0))))} -> LAWN PLUGS
B60: 46003 | C60: Invoice | D60: 89621 | E60: CENTRAL NURSERY DEPOT | F60: AT LAWN PLUG SEEDLINGS 128 | G60: 5 | H60: 124.3 | I60: 621.5 | J60: 1253.25 | K60: {=_xlfn.LET(_xlpm.d,UPPER(TRIM(CLEAN(SUBSTITUTE(F60,CHAR(160)," ")))),_xlpm.keys,UPPER(TRIM(MAP!$B$2:$B$1000)),_xlpm.vals,MAP!$A$2:$A$1000,_xlpm.matchlen,IF(ISNUMBER(SEARCH(_xlpm.keys,_xlpm.d)),LEN(_xlpm.keys),0),_xlpm.best,MAX(_xlpm.matchlen),IF(_xlpm.best=0,"",INDEX(_xlpm.vals,MATCH(_xlpm.best,_xlpm.matchlen,0))))} -> LAWN PLUGS
B61: 46045 | C61: Invoice | D61: 89974 | E61: BUILDERS WAREHOUSE:RIVONIA | F61: AT LAWN PLUG SEEDLINGS 128 | G61: 5 | H61: 126.35 | I61: 631.75 | J61: 1885 | K61: {=_xlfn.LET(_xlpm.d,UPPER(TRIM(CLEAN(SUBSTITUTE(F61,CHAR(160)," ")))),_xlpm.keys,UPPER(TRIM(MAP!$B$2:$B$1000)),_xlpm.vals,MAP!$A$2:$A$1000,_xlpm.matchlen,IF(ISNUMBER(SEARCH(_xlpm.keys,_xlpm.d)),LEN(_xlpm.keys),0),_xlpm.best,MAX(_xlpm.matchlen),IF(_xlpm.best=0,"",INDEX(_xlpm.vals,MATCH(_xlpm.best,_xlpm.matchlen,0))))} -> LAWN PLUGS
B62: 46052 | C62: Invoice | D62: 90030 | E62: BUILDERS WAREHOUSE:RIVONIA | F62: AT LAWN PLUG SEEDLINGS 128 | G62: 2 | H62: 126.35 | I62: 252.7 | J62: 2137.7 | K62: {=_xlfn.LET(_xlpm.d,UPPER(TRIM(CLEAN(SUBSTITUTE(F62,CHAR(160)," ")))),_xlpm.keys,UPPER(TRIM(MAP!$B$2:$B$1000)),_xlpm.vals,MAP!$A$2:$A$1000,_xlpm.matchlen,IF(ISNUMBER(SEARCH(_xlpm.keys,_xlpm.d)),LEN(_xlpm.keys),0),_xlpm.best,MAX(_xlpm.matchlen),IF(_xlpm.best=0,"",INDEX(_xlpm.vals,MATCH(_xlpm.best,_xlpm.matchlen,0))))} -> LAWN PLUGS
...

Sheet MAP
A1: 12CM COLOUR POT | B1: AT SEASONAL COLOUR 12CM POT | E1: SEEDLINGS
A2: 12CM COLOUR POT | B2: CELOSIA 12CM | E2: 15CM COLOUR POTS
A3: 12CM COLOUR POT | B3: AT HYPOESTES POT 12CM 850040155 | E3: 12CM COLOUR POT
A4: 12CM COLOUR POT | B4: AT IMPATIENS POT 12CM 850040109 | E4: 12CM HERB
A5: 12CM COLOUR POT | B5: COLOUR MAGIC 12CM | E5: PETUNIA HYBRIDS
A6: 12CM COLOUR POT | B6: PETUNIA 12CM | E6: PLANT TO PLATE
A7: 12CM PRIMROSE/OBCONICA | B7: PRIMROSE | E7: SIMPLY BEAUTIFUL
A8: 12CM COLOUR POT | B8: VINCA VICTORY GRAPE | E8: MID RANGE
A9: 12CM COLOUR POT | B9: FLOWER POT 12CM | E9: CALIBRACHOA
A10: 12CM HERB/VEG | B10: BASIL | E10: 20CM AERO BOWL
A11: 12CM HERB/VEG | B11: CHIVES | E11: 14CM SUCCULENTS
A12: 12CM HERB/VEG | B12: CORIANDER | E12: 25CM HANGING BASKET
... A24: 12CM HERB/VEG | B24: HERB L/STYLE | E24: CHILLI POT
A25: 12CM ORNAMENTAL CHILLI | B25: ORNAMENTAL CHILLI
A26: 12CM ORNAMENTAL CHILLI | B26: CHILLI ORNAMENTAL
A27: 12CM PATIO RANGE | B27: CALCEOLARIA | E27: LAWN PLUGS
A28: 12CM PATIO RANGE | B28: CINERARIA | E28: 12CM GRASS POTS
A29: 12CM PATIO RANGE | B29: CYCLAMEN | E29: 17CM GERANIUM
A30: 15CM COLOUR POTS | B30: PELARGONIUM
A31: 15CM COLOUR POTS | B31: ALYSSUM CLEAR CRYSTAL
A32: 15CM COLOUR POTS | B32: ANTIRRHINUM
A33: 15CM COLOUR POTS | B33: DIANTHUS
A34: 15CM COLOUR POTS | B34: CELOSIA DRACULA
A35: 15CM COLOUR POTS | B35: COLOUR MAGIC 15CM
A36: 15CM COLOUR POTS | B36: COLOUR MAGIC ALYSSUM
A37: 15CM COLOUR POTS | B37: COLOUR MAGIC BELLIS
A38: 15CM COLOUR POTS | B38: COLOUR MAGIC CALENDULA
A39: 15CM COLOUR POTS | B39: COLOUR MAGIC DIANTHUS
A40: 15CM COLOUR POTS | B40: COLOUR MAGIC GAZANIA
A41: 15CM COLOUR POTS | B41: COLOUR MAGIC GYPSOPHILLA
... A109: COLOUR PLUGS 48 | B109: COLOUR PLUGS 48
A110: SEEDLINGS | B110: 28884
A111: SEEDLINGS | B111: SEEDLING FLOWER 6 PACK
A112: SEEDLINGS | B112: SEEDLING VEGETABLE 6 PACK
A113: SEEDLINGS | B113: VEGETABLE SEEDLINGS 6 PACK
A114: 9CM SUCCULENTS | B114: COLOUR MAGIC 9CM
A115: 9CM SUCCULENTS | B115: ECHEVERIA SET OLIVER
A116: 9CM SUCCULENTS | B116: SUCCULENT 9CM
A117: ADVERTISING | B117: ADVERTISING
A118: BUILDERS REBATE | B118: BUILDERS REBATE
...

Sheet TABLE
A1: Years (Date) | B1: 2026
A2: Months (Date) | B2: Apr
A3: Date | B3: (All)
A5: Row Labels | B5: Sum of Quantity | C5: Percentage
A6: 128 COLOUR PLUGS | B6: 10 | C6: 0.00013505301
A7: 12CM COLOUR POT | B7: 2521 | C7: 0.034046863
A8: 12CM GRASS POTS | B8: 6 | C8: 8.1031805e-05
A9: 12CM HERB/VEG | B9: 2932 | C9: 0.039597542
A10: 12CM ORNAMENTAL CHILLI | B10: 50 | C10: 0.00067526504
A11: 12CM PATIO RANGE | B11: 14 | C11: 0.00018907421
A12: 14CM SUCCULENTS | B12: 49 | C12: 0.00066175974
A13: 15CM ANGELONIA | B13: 38 | C13: 0.00051320143
A14: 15CM COLOUR POTS | B14: 11389 | C14: 0.15381187
A15: 20CM AERO BOWL | B15: 833 | C15: 0.011249916
A16: 24 PACKS | B16: 134 | C16: 0.0018097103
A17: 25CM COLOUR POT | B17: 519 | C17: 0.0070092511
... A32: Grand Total | B32: 74045 | C32: 1
