Workbook

Sheet RETURN MASTER
A1: Column1 | B1: Date | C1: Transaction type | D1: Number | E1: Customer full name | F1: Memo/Description | G1: Quantity | H1: Sales price | I1: Amount | J1: Balance | K1: Line
A2: 128 LM LAWN | K2: {=_xlfn.LET(_xlpm.d,UPPER(TRIM(CLEAN(SUBSTITUTE(F2,CHAR(160)," ")))),_xlpm.keys,UPPER(TRIM(MAP!$B$1:$B$401)),_xlpm.vals,MAP!$A$1:$A$401,_xlpm.matchlen,IF(ISNUMBER(SEARCH(_xlpm.keys,_xlpm.d)),LEN(_xlpm.keys),0),_xlpm.best,MAX(_xlpm.matchlen),IF(_xlpm.best=0,"",INDEX(_xlpm.vals,MATCH(_xlpm.best,_xlpm.matchlen,0))))}
B3: 45786 | C3: Credit Note | D3: 26571 | E3: LIFESTYLE HOME GARDEN | F3: 128 LM LAWN | G3: -10 | H3: 69.95 | I3: -699.5 | J3: -699.5 | K3: {=_xlfn.LET(_xlpm.d,UPPER(TRIM(CLEAN(SUBSTITUTE(F3,CHAR(160)," ")))),_xlpm.keys,UPPER(TRIM(MAP!$B$1:$B$401)),_xlpm.vals,MAP!$A$1:$A$401,_xlpm.matchlen,IF(ISNUMBER(SEARCH(_xlpm.keys,_xlpm.d)),LEN(_xlpm.keys),0),_xlpm.best,MAX(_xlpm.matchlen),IF(_xlpm.best=0,"",INDEX(_xlpm.vals,MATCH(_xlpm.best,_xlpm.matchlen,0))))} -> LAWN PLUGS
B4: 46029 | C4: Credit Note | D4: 16060 | E4: GARDENSHOP PARKTOWN | F4: 128 LM LAWN | G4: -6 | H4: 124.3 | I4: -745.8 | J4: -1445.3 | K4: {=_xlfn.LET(_xlpm.d,UPPER(TRIM(CLEAN(SUBSTITUTE(F4,CHAR(160)," ")))),_xlpm.keys,UPPER(TRIM(MAP!$B$1:$B$401)),_xlpm.vals,MAP!$A$1:$A$401,_xlpm.matchlen,IF(ISNUMBER(SEARCH(_xlpm.keys,_xlpm.d)),LEN(_xlpm.keys),0),_xlpm.best,MAX(_xlpm.matchlen),IF(_xlpm.best=0,"",INDEX(_xlpm.vals,MATCH(_xlpm.best,_xlpm.matchlen,0))))} -> LAWN PLUGS
A5: Total for 128 LM LAWN | G5: -16 | I5: =I3+I4 -> -1445.3 | K5: {=_xlfn.LET(_xlpm.d,UPPER(TRIM(CLEAN(SUBSTITUTE(F5,CHAR(160)," ")))),_xlpm.keys,UPPER(TRIM(MAP!$B$1:$B$401)),_xlpm.vals,MAP!$A$1:$A$401,_xlpm.matchlen,IF(ISNUMBER(SEARCH(_xlpm.keys,_xlpm.d)),LEN(_xlpm.keys),0),_xlpm.best,MAX(_xlpm.matchlen),IF(_xlpm.best=0,"",INDEX(_xlpm.vals,MATCH(_xlpm.best,_xlpm.matchlen,0))))}
A6: AT LAWN PLUG SEEDLINGS 128 | K6: {=_xlfn.LET(_xlpm.d,UPPER(TRIM(CLEAN(SUBSTITUTE(F6,CHAR(160)," ")))),_xlpm.keys,UPPER(TRIM(MAP!$B$1:$B$401)),_xlpm.vals,MAP!$A$1:$A$401,_xlpm.matchlen,IF(ISNUMBER(SEARCH(_xlpm.keys,_xlpm.d)),LEN(_xlpm.keys),0),_xlpm.best,MAX(_xlpm.matchlen),IF(_xlpm.best=0,"",INDEX(_xlpm.vals,MATCH(_xlpm.best,_xlpm.matchlen,0))))}
B7: 46070 | C7: Credit Note | D7: 4401602785 | E7: BUILDERS WAREHOUSE:RIVONIA | F7: AT LAWN PLUG SEEDLINGS 128 850040203 | G7: -1 | H7: 126.35 | I7: -126.35 | J7: -126.35 | K7: {=_xlfn.LET(_xlpm.d,UPPER(TRIM(CLEAN(SUBSTITUTE(F7,CHAR(160)," ")))),_xlpm.keys,UPPER(TRIM(MAP!$B$1:$B$401)),_xlpm.vals,MAP!$A$1:$A$401,_xlpm.matchlen,IF(ISNUMBER(SEARCH(_xlpm.keys,_xlpm.d)),LEN(_xlpm.keys),0),_xlpm.best,MAX(_xlpm.matchlen),IF(_xlpm.best=0,"",INDEX(_xlpm.vals,MATCH(_xlpm.best,_xlpm.matchlen,0))))} -> LAWN PLUGS
A8: Total for AT LAWN PLUG SEEDLINGS 128 | G8: -1 | I8: =I7 -> -126.35 | K8: {=_xlfn.LET(_xlpm.d,UPPER(TRIM(CLEAN(SUBSTITUTE(F8,CHAR(160)," ")))),_xlpm.keys,UPPER(TRIM(MAP!$B$1:$B$401)),_xlpm.vals,MAP!$A$1:$A$401,_xlpm.matchlen,IF(ISNUMBER(SEARCH(_xlpm.keys,_xlpm.d)),LEN(_xlpm.keys),0),_xlpm.best,MAX(_xlpm.matchlen),IF(_xlpm.best=0,"",INDEX(_xlpm.vals,MATCH(_xlpm.best,_xlpm.matchlen,0))))}
A9: AT HYPOESTES POT 12CM | K9: {=_xlfn.LET(_xlpm.d,UPPER(TRIM(CLEAN(SUBSTITUTE(F9,CHAR(160)," ")))),_xlpm.keys,UPPER(TRIM(MAP!$B$1:$B$401)),_xlpm.vals,MAP!$A$1:$A$401,_xlpm.matchlen,IF(ISNUMBER(SEARCH(_xlpm.keys,_xlpm.d)),LEN(_xlpm.keys),0),_xlpm.best,MAX(_xlpm.matchlen),IF(_xlpm.best=0,"",INDEX(_xlpm.vals,MATCH(_xlpm.best,_xlpm.matchlen,0))))}
B10: 46063 | C10: Credit Note | D10: 4401600447 | E10: BUILDERS WAREHOUSE:ERASMUS PARK | F10: AT HYPOESTES POT 12CM 850040155 | G10: -8 | H10: 12.2 | I10: -97.6 | J10: -97.6 | K10: {=_xlfn.LET(_xlpm.d,UPPER(TRIM(CLEAN(SUBSTITUTE(F10,CHAR(160)," ")))),_xlpm.keys,UPPER(TRIM(MAP!$B$1:$B$401)),_xlpm.vals,MAP!$A$1:$A$401,_xlpm.matchlen,IF(ISNUMBER(SEARCH(_xlpm.keys,_xlpm.d)),LEN(_xlpm.keys),0),_xlpm.best,MAX(_xlpm.matchlen),IF(_xlpm.best=0,"",INDEX(_xlpm.vals,MATCH(_xlpm.best,_xlpm.matchlen,0))))} -> 12CM COLOUR POT
A11: Total for AT HYPOESTES POT 12CM | G11: -8 | I11: =I10 -> -97.6 | K11: {=_xlfn.LET(_xlpm.d,UPPER(TRIM(CLEAN(SUBSTITUTE(F11,CHAR(160)," ")))),_xlpm.keys,UPPER(TRIM(MAP!$B$1:$B$401)),_xlpm.vals,MAP!$A$1:$A$401,_xlpm.matchlen,IF(ISNUMBER(SEARCH(_xlpm.keys,_xlpm.d)),LEN(_xlpm.keys),0),_xlpm.best,MAX(_xlpm.matchlen),IF(_xlpm.best=0,"",INDEX(_xlpm.vals,MATCH(_xlpm.best,_xlpm.matchlen,0))))}
A12: AT IMPATIENS POT 12CM | K12: {=_xlfn.LET(_xlpm.d,UPPER(TRIM(CLEAN(SUBSTITUTE(F12,CHAR(160)," ")))),_xlpm.keys,UPPER(TRIM(MAP!$B$1:$B$401)),_xlpm.vals,MAP!$A$1:$A$401,_xlpm.matchlen,IF(ISNUMBER(SEARCH(_xlpm.keys,_xlpm.d)),LEN(_xlpm.keys),0),_xlpm.best,MAX(_xlpm.matchlen),IF(_xlpm.best=0,"",INDEX(_xlpm.vals,MATCH(_xlpm.best,_xlpm.matchlen,0))))}
B13: 46079 | C13: Credit Note | D13: 4401605618 | E13: BUILDERS WAREHOUSE:KEMPTON PARK | F13: AT IMPATIENS POT 12CM 850040109 | G13: -25 | H13: 12.2 | I13: -305 | J13: -305 | K13: {=_xlfn.LET(_xlpm.d,UPPER(TRIM(CLEAN(SUBSTITUTE(F13,CHAR(160)," ")))),_xlpm.keys,UPPER(TRIM(MAP!$B$1:$B$401)),_xlpm.vals,MAP!$A$1:$A$401,_xlpm.matchlen,IF(ISNUMBER(SEARCH(_xlpm.keys,_xlpm.d)),LEN(_xlpm.keys),0),_xlpm.best,MAX(_xlpm.matchlen),IF(_xlpm.best=0,"",INDEX(_xlpm.vals,MATCH(_xlpm.best,_xlpm.matchlen,0))))} -> 12CM COLOUR POT
A14: Total for AT IMPATIENS POT 12CM | G14: -25 | I14: =I13 -> -305 | K14: {=_xlfn.LET(_xlpm.d,UPPER(TRIM(CLEAN(SUBSTITUTE(F14,CHAR(160)," ")))),_xlpm.keys,UPPER(TRIM(MAP!$B$1:$B$401)),_xlpm.vals,MAP!$A$1:$A$401,_xlpm.matchlen,IF(ISNUMBER(SEARCH(_xlpm.keys,_xlpm.d)),LEN(_xlpm.keys),0),_xlpm.best,MAX(_xlpm.matchlen),IF(_xlpm.best=0,"",INDEX(_xlpm.vals,MATCH(_xlpm.best,_xlpm.matchlen,0))))}
A15: AT PETUNIA HYBRIDS POT 12CM | K15: {=_xlfn.LET(_xlpm.d,UPPER(TRIM(CLEAN(SUBSTITUTE(F15,CHAR(160)," ")))),_xlpm.keys,UPPER(TRIM(MAP!$B$1:$B$401)),_xlpm.vals,MAP!$A$1:$A$401,_xlpm.matchlen,IF(ISNUMBER(SEARCH(_xlpm.keys,_xlpm.d)),LEN(_xlpm.keys),0),_xlpm.best,MAX(_xlpm.matchlen),IF(_xlpm.best=0,"",INDEX(_xlpm.vals,MATCH(_xlpm.best,_xlpm.matchlen,0))))}
B16: 46027 | C16: Credit Note | D16: 89764A | E16: BUILDERS WAREHOUSE:NEWMARKET | F16: AT PETUNIA HYBRIDS POT 12CM 850040146 | G16: -30 | H16: 27.95 | I16: -838.5 | J16: -838.5 | K16: {=_xlfn.LET(_xlpm.d,UPPER(TRIM(CLEAN(SUBSTITUTE(F16,CHAR(160)," ")))),_xlpm.keys,UPPER(TRIM(MAP!$B$1:$B$401)),_xlpm.vals,MAP!$A$1:$A$401,_xlpm.matchlen,IF(ISNUMBER(SEARCH(_xlpm.keys,_xlpm.d)),LEN(_xlpm.keys),0),_xlpm.best,MAX(_xlpm.matchlen),IF(_xlpm.best=0,"",INDEX(_xlpm.vals,MATCH(_xlpm.best,_xlpm.matchlen,0))))} -> 12CM PETUNIA HYBRIDS
B17: 46028 | C17: Credit Note | D17: 89772A | E17: BUILDERS WAREHOUSE:SILVERLAKES | F17: AT PETUNIA HYBRIDS POT 12CM 850040146 | G17: -2 | H17: 27.95 | I17: -55.9 | J17: -894.4 | K17: {=_xlfn.LET(_xlpm.d,UPPER(TRIM(CLEAN(SUBSTITUTE(F17,CHAR(160)," ")))),_xlpm.keys,UPPER(TRIM(MAP!$B$1:$B$401)),_xlpm.vals,MAP!$A$1:$A$401,_xlpm.matchlen,IF(ISNUMBER(SEARCH(_xlpm.keys,_xlpm.d)),LEN(_xlpm.keys),0),_xlpm.best,MAX(_xlpm.matchlen),IF(_xlpm.best=0,"",INDEX(_xlpm.vals,MATCH(_xlpm.best,_xlpm.matchlen,0))))} -> 12CM PETUNIA HYBRIDS
B18: 46035 | C18: Credit Note | D18: 4401592795 | E18: BUILDERS WAREHOUSE:ZAMBEZI | F18: AT PETUNIA HYBRIDS POT 12CM 850040146 | G18: -5 | H18: 27.95 | I18: -139.75 | J18: -1034.15 | K18: {=_xlfn.LET(_xlpm.d,UPPER(TRIM(CLEAN(SUBSTITUTE(F18,CHAR(160)," ")))),_xlpm.keys,UPPER(TRIM(MAP!$B$1:$B$401)),_xlpm.vals,MAP!$A$1:$A$401,_xlpm.matchlen,IF(ISNUMBER(SEARCH(_xlpm.keys,_xlpm.d)),LEN(_xlpm.keys),0),_xlpm.best,MAX(_xlpm.matchlen),IF(_xlpm.best=0,"",INDEX(_xlpm.vals,MATCH(_xlpm.best,_xlpm.matchlen,0))))} -> 12CM PETUNIA HYBRIDS
B19: 46049 | C19: Credit Note | D19: 4401596213 | E19: BUILDERS WAREHOUSE:ZAMBEZI | F19: AT PETUNIA HYBRIDS POT 12CM 850040146 | G19: -4 | H19: 27.95 | I19: -111.8 | J19: -1145.95 | K19: {=_xlfn.LET(_xlpm.d,UPPER(TRIM(CLEAN(SUBSTITUTE(F19,CHAR(160)," ")))),_xlpm.keys,UPPER(TRIM(MAP!$B$1:$B$401)),_xlpm.vals,MAP!$A$1:$A$401,_xlpm.matchlen,IF(ISNUMBER(SEARCH(_xlpm.keys,_xlpm.d)),LEN(_xlpm.keys),0),_xlpm.best,MAX(_xlpm.matchlen),IF(_xlpm.best=0,"",INDEX(_xlpm.vals,MATCH(_xlpm.best,_xlpm.matchlen,0))))} -> 12CM PETUNIA HYBRIDS
B20: 46056 | C20: Credit Note | D20: 4401598139 | E20: BUILDERS WAREHOUSE:LYNNWOOD | F20: AT PETUNIA HYBRIDS POT 12CM 850040146 | G20: -10 | H20: 27.95 | I20: -279.5 | J20: -1425.45 | K20: {=_xlfn.LET(_xlpm.d,UPPER(TRIM(CLEAN(SUBSTITUTE(F20,CHAR(160)," ")))),_xlpm.keys,UPPER(TRIM(MAP!$B$1:$B$401)),_xlpm.vals,MAP!$A$1:$A$401,_xlpm.matchlen,IF(ISNUMBER(SEARCH(_xlpm.keys,_xlpm.d)),LEN(_xlpm.keys),0),_xlpm.best,MAX(_xlpm.matchlen),IF(_xlpm.best=0,"",INDEX(_xlpm.vals,MATCH(_xlpm.best,_xlpm.matchlen,0))))} -> 12CM PETUNIA HYBRIDS
B21: 46066 | C21: Credit Note | D21: 4401601731 | E21: BUILDERS WAREHOUSE:NEWMARKET | F21: AT PETUNIA HYBRIDS POT 12CM 850040146 | G21: -15 | H21: 27.95 | I21: -419.25 | J21: -1844.7 | K21: {=_xlfn.LET(_xlpm.d,UPPER(TRIM(CLEAN(SUBSTITUTE(F21,CHAR(160)," ")))),_xlpm.keys,UPPER(TRIM(MAP!$B$1:$B$401)),_xlpm.vals,MAP!$A$1:$A$401,_xlpm.matchlen,IF(ISNUMBER(SEARCH(_xlpm.keys,_xlpm.d)),LEN(_xlpm.keys),0),_xlpm.best,MAX(_xlpm.matchlen),IF(_xlpm.best=0,"",INDEX(_xlpm.vals,MATCH(_xlpm.best,_xlpm.matchlen,0))))} -> 12CM PETUNIA HYBRIDS
B22: 46070 | C22: Credit Note | D22: 4401602766 | E22: BUILDERS WAREHOUSE:CENTURION | F22: AT PETUNIA HYBRIDS POT 12CM 850040146 | G22: -40 | H22: 27.95 | I22: -1118 | J22: -2962.7 | K22: {=_xlfn.LET(_xlpm.d,UPPER(TRIM(CLEAN(SUBSTITUTE(F22,CHAR(160)," ")))),_xlpm.keys,UPPER(TRIM(MAP!$B$1:$B$401)),_xlpm.vals,MAP!$A$1:$A$401,_xlpm.matchlen,IF(ISNUMBER(SEARCH(_xlpm.keys,_xlpm.d)),LEN(_xlpm.keys),0),_xlpm.best,MAX(_xlpm.matchlen),IF(_xlpm.best=0,"",INDEX(_xlpm.vals,MATCH(_xlpm.best,_xlpm.matchlen,0))))} -> 12CM PETUNIA HYBRIDS
B23: 46071 | C23: Credit Note | D23: 4401603219 | E23: BUILDERS WAREHOUSE:ZAMBEZI | F23: AT PETUNIA HYBRIDS POT 12CM 850040146 | G23: -15 | H23: 27.95 | I23: -419.25 | J23: -3381.95 | K23: {=_xlfn.LET(_xlpm.d,UPPER(TRIM(CLEAN(SUBSTITUTE(F23,CHAR(160)," ")))),_xlpm.keys,UPPER(TRIM(MAP!$B$1:$B$401)),_xlpm.vals,MAP!$A$1:$A$401,_xlpm.matchlen,IF(ISNUMBER(SEARCH(_xlpm.keys,_xlpm.d)),LEN(_xlpm.keys),0),_xlpm.best,MAX(_xlpm.matchlen),IF(_xlpm.best=0,"",INDEX(_xlpm.vals,MATCH(_xlpm.best,_xlpm.matchlen,0))))} -> 12CM PETUNIA HYBRIDS
B24: 46072 | C24: Credit Note | D24: 4401603572 | E24: BUILDERS WAREHOUSE:FLORIDA GLEN | F24: AT PETUNIA HYBRIDS POT 12CM 850040146 | G24: -12 | H24: 27.95 | I24: -335.4 | J24: -3717.35 | K24: {=_xlfn.LET(_xlpm.d,UPPER(TRIM(CLEAN(SUBSTITUTE(F24,CHAR(160)," ")))),_xlpm.keys,UPPER(TRIM(MAP!$B$1:$B$401)),_xlpm.vals,MAP!$A$1:$A$401,_xlpm.matchlen,IF(ISNUMBER(SEARCH(_xlpm.keys,_xlpm.d)),LEN(_xlpm.keys),0),_xlpm.best,MAX(_xlpm.matchlen),IF(_xlpm.best=0,"",INDEX(_xlpm.vals,MATCH(_xlpm.best,_xlpm.matchlen,0))))} -> 12CM PETUNIA HYBRIDS
B25: 46073 | C25: Credit Note | D25: 4401604001 | E25: BUILDERS WAREHOUSE:LAMBTON | F25: AT PETUNIA HYBRIDS POT 12CM 850040146 | G25: -6 | H25: 27.95 | I25: -167.7 | J25: -3885.05 | K25: {=_xlfn.LET(_xlpm.d,UPPER(TRIM(CLEAN(SUBSTITUTE(F25,CHAR(160)," ")))),_xlpm.keys,UPPER(TRIM(MAP!$B$1:$B$401)),_xlpm.vals,MAP!$A$1:$A$401,_xlpm.matchlen,IF(ISNUMBER(SEARCH(_xlpm.keys,_xlpm.d)),LEN(_xlpm.keys),0),_xlpm.best,MAX(_xlpm.matchlen),IF(_xlpm.best=0,"",INDEX(_xlpm.vals,MATCH(_xlpm.best,_xlpm.matchlen,0))))} -> 12CM PETUNIA HYBRIDS
B26: 46077 | C26: Credit Note | D26: 4401604949 | E26: BUILDERS WAREHOUSE:SILVERLAKES | F26: AT PETUNIA HYBRIDS POT 12CM 850040146 | G26: -26 | H26: 27.95 | I26: -726.7 | J26: -4611.75 | K26: {=_xlfn.LET(_xlpm.d,UPPER(TRIM(CLEAN(SUBSTITUTE(F26,CHAR(160)," ")))),_xlpm.keys,UPPER(TRIM(MAP!$B$1:$B$401)),_xlpm.vals,MAP!$A$1:$A$401,_xlpm.matchlen,IF(ISNUMBER(SEARCH(_xlpm.keys,_xlpm.d)),LEN(_xlpm.keys),0),_xlpm.best,MAX(_xlpm.matchlen),IF(_xlpm.best=0,"",INDEX(_xlpm.vals,MATCH(_xlpm.best,_xlpm.matchlen,0))))} -> 12CM PETUNIA HYBRIDS
B27: 46084 | C27: Credit Note | D27: 4401606629 | E27: BUILDERS WAREHOUSE:ZAMBEZI | F27: AT PETUNIA HYBRIDS POT 12CM 850040146 | G27: -8 | H27: 27.95 | I27: -223.6 | J27: -4835.35 | K27: {=_xlfn.LET(_xlpm.d,UPPER(TRIM(CLEAN(SUBSTITUTE(F27,CHAR(160)," ")))),_xlpm.keys,UPPER(TRIM(MAP!$B$1:$B$401)),_xlpm.vals,MAP!$A$1:$A$401,_xlpm.matchlen,IF(ISNUMBER(SEARCH(_xlpm.keys,_xlpm.d)),LEN(_xlpm.keys),0),_xlpm.best,MAX(_xlpm.matchlen),IF(_xlpm.best=0,"",INDEX(_xlpm.vals,MATCH(_xlpm.best,_xlpm.matchlen,0))))} -> 12CM PETUNIA HYBRIDS
... B32: 46112 | C32: Credit Note | D32: 4401615755 | E32: BUILDERS WAREHOUSE:RUSTENBURG | F32: AT PETUNIA HYBRIDS POT 12CM 850040146 | G32: -7 | H32: 27.95 | I32: -195.65 | J32: -6121.05 | K32: {=_xlfn.LET(_xlpm.d,UPPER(TRIM(CLEAN(SUBSTITUTE(F32,CHAR(160)," ")))),_xlpm.keys,UPPER(TRIM(MAP!$B$1:$B$401)),_xlpm.vals,MAP!$A$1:$A$401,_xlpm.matchlen,IF(ISNUMBER(SEARCH(_xlpm.keys,_xlpm.d)),LEN(_xlpm.keys),0),_xlpm.best,MAX(_xlpm.matchlen),IF(_xlpm.best=0,"",INDEX(_xlpm.vals,MATCH(_xlpm.best,_xlpm.matchlen,0))))} -> 12CM PETUNIA HYBRIDS
A33: Total for AT PETUNIA HYBRIDS POT 12CM | G33: -219 | I33: =I16+I17+I18+I19+I20+I21+I22+I23+I24+I25+I26+I27+I28+I29+I30+I31+I32 -> -6121.05 | K33: {=_xlfn.LET(_xlpm.d,UPPER(TRIM(CLEAN(SUBSTITUTE(F33,CHAR(160)," ")))),_xlpm.keys,UPPER(TRIM(MAP!$B$1:$B$401)),_xlpm.vals,MAP!$A$1:$A$401,_xlpm.matchlen,IF(ISNUMBER(SEARCH(_xlpm.keys,_xlpm.d)),LEN(_xlpm.keys),0),_xlpm.best,MAX(_xlpm.matchlen),IF(_xlpm.best=0,"",INDEX(_xlpm.vals,MATCH(_xlpm.best,_xlpm.matchlen,0))))}
A34: AT SEASONAL COLOUR 12CM POT | K34: {=_xlfn.LET(_xlpm.d,UPPER(TRIM(CLEAN(SUBSTITUTE(F34,CHAR(160)," ")))),_xlpm.keys,UPPER(TRIM(MAP!$B$1:$B$401)),_xlpm.vals,MAP!$A$1:$A$401,_xlpm.matchlen,IF(ISNUMBER(SEARCH(_xlpm.keys,_xlpm.d)),LEN(_xlpm.keys),0),_xlpm.best,MAX(_xlpm.matchlen),IF(_xlpm.best=0,"",INDEX(_xlpm.vals,MATCH(_xlpm.best,_xlpm.matchlen,0))))}
B35: 45982 | C35: Credit Note | D35: 89309A | E35: BUILDERS WAREHOUSE:BOKSBURG (NEW) | F35: AT SEASONAL COLOUR 12CM POT 850040171 | G35: -30 | H35: 7 | I35: -210 | J35: -210 | K35: {=_xlfn.LET(_xlpm.d,UPPER(TRIM(CLEAN(SUBSTITUTE(F35,CHAR(160)," ")))),_xlpm.keys,UPPER(TRIM(MAP!$B$1:$B$401)),_xlpm.vals,MAP!$A$1:$A$401,_xlpm.matchlen,IF(ISNUMBER(SEARCH(_xlpm.keys,_xlpm.d)),LEN(_xlpm.keys),0),_xlpm.best,MAX(_xlpm.matchlen),IF(_xlpm.best=0,"",INDEX(_xlpm.vals,MATCH(_xlpm.best,_xlpm.matchlen,0))))} -> 12CM COLOUR POT
B36: 45989 | C36: Credit Note | D36: 89414A | E36: BUILDERS WAREHOUSE:ZAMBEZI | F36: AT SEASONAL COLOUR 12CM POT | G36: -4 | H36: 7 | I36: -28 | J36: -238 | K36: {=_xlfn.LET(_xlpm.d,UPPER(TRIM(CLEAN(SUBSTITUTE(F36,CHAR(160)," ")))),_xlpm.keys,UPPER(TRIM(MAP!$B$1:$B$401)),_xlpm.vals,MAP!$A$1:$A$401,_xlpm.matchlen,IF(ISNUMBER(SEARCH(_xlpm.keys,_xlpm.d)),LEN(_xlpm.keys),0),_xlpm.best,MAX(_xlpm.matchlen),IF(_xlpm.best=0,"",INDEX(_xlpm.vals,MATCH(_xlpm.best,_xlpm.matchlen,0))))} -> 12CM COLOUR POT
B37: 45993 | C37: Credit Note | D37: 4401584725 | E37: BUILDERS WAREHOUSE:RUSTENBURG | F37: AT SEASONAL COLOUR 12CM POT 850040171 | G37: -3 | H37: 7 | I37: -21 | J37: -259 | K37: {=_xlfn.LET(_xlpm.d,UPPER(TRIM(CLEAN(SUBSTITUTE(F37,CHAR(160)," ")))),_xlpm.keys,UPPER(TRIM(MAP!$B$1:$B$401)),_xlpm.vals,MAP!$A$1:$A$401,_xlpm.matchlen,IF(ISNUMBER(SEARCH(_xlpm.keys,_xlpm.d)),LEN(_xlpm.keys),0),_xlpm.best,MAX(_xlpm.matchlen),IF(_xlpm.best=0,"",INDEX(_xlpm.vals,MATCH(_xlpm.best,_xlpm.matchlen,0))))} -> 12CM COLOUR POT
B38: 45994 | C38: Credit Note | D38: 4401585073 | E38: BUILDERS WAREHOUSE:SOUTHGATE | F38: AT SEASONAL COLOUR 12CM POT 850040171 | G38: -19 | H38: 7 | I38: -133 | J38: -392 | K38: {=_xlfn.LET(_xlpm.d,UPPER(TRIM(CLEAN(SUBSTITUTE(F38,CHAR(160)," ")))),_xlpm.keys,UPPER(TRIM(MAP!$B$1:$B$401)),_xlpm.vals,MAP!$A$1:$A$401,_xlpm.matchlen,IF(ISNUMBER(SEARCH(_xlpm.keys,_xlpm.d)),LEN(_xlpm.keys),0),_xlpm.best,MAX(_xlpm.matchlen),IF(_xlpm.best=0,"",INDEX(_xlpm.vals,MATCH(_xlpm.best,_xlpm.matchlen,0))))} -> 12CM COLOUR POT
B39: 45996 | C39: Credit Note | D39: 4401585670 | E39: BUILDERS WAREHOUSE:GLEN EAGLES | F39: AT SEASONAL COLOUR 12CM POT 850040171 | G39: -8 | H39: 7 | I39: -56 | J39: -448 | K39: {=_xlfn.LET(_xlpm.d,UPPER(TRIM(CLEAN(SUBSTITUTE(F39,CHAR(160)," ")))),_xlpm.keys,UPPER(TRIM(MAP!$B$1:$B$401)),_xlpm.vals,MAP!$A$1:$A$401,_xlpm.matchlen,IF(ISNUMBER(SEARCH(_xlpm.keys,_xlpm.d)),LEN(_xlpm.keys),0),_xlpm.best,MAX(_xlpm.matchlen),IF(_xlpm.best=0,"",INDEX(_xlpm.vals,MATCH(_xlpm.best,_xlpm.matchlen,0))))} -> 12CM COLOUR POT
B40: 45996 | C40: Credit Note | D40: 89534A | E40: BUILDERS WAREHOUSE:CARNIVAL MALL | F40: AT SEASONAL COLOUR 12CM POT | G40: -25 | H40: 7 | I40: -175 | J40: -623 | K40: {=_xlfn.LET(_xlpm.d,UPPER(TRIM(CLEAN(SUBSTITUTE(F40,CHAR(160)," ")))),_xlpm.keys,UPPER(TRIM(MAP!$B$1:$B$401)),_xlpm.vals,MAP!$A$1:$A$401,_xlpm.matchlen,IF(ISNUMBER(SEARCH(_xlpm.keys,_xlpm.d)),LEN(_xlpm.keys),0),_xlpm.best,MAX(_xlpm.matchlen),IF(_xlpm.best=0,"",INDEX(_xlpm.vals,MATCH(_xlpm.best,_xlpm.matchlen,0))))} -> 12CM COLOUR POT
B41: 45996 | C41: Credit Note | D41: 89531A | E41: BUILDERS WAREHOUSE:BOKSBURG (NEW) | F41: AT SEASONAL COLOUR 12CM POT 850040171 | G41: -1 | H41: 7 | I41: -7 | J41: -630 | K41: {=_xlfn.LET(_xlpm.d,UPPER(TRIM(CLEAN(SUBSTITUTE(F41,CHAR(160)," ")))),_xlpm.keys,UPPER(TRIM(MAP!$B$1:$B$401)),_xlpm.vals,MAP!$A$1:$A$401,_xlpm.matchlen,IF(ISNUMBER(SEARCH(_xlpm.keys,_xlpm.d)),LEN(_xlpm.keys),0),_xlpm.best,MAX(_xlpm.matchlen),IF(_xlpm.best=0,"",INDEX(_xlpm.vals,MATCH(_xlpm.best,_xlpm.matchlen,0))))} -> 12CM COLOUR POT
B42: 46001 | C42: Credit Note | D42: 4401586981 | E42: BUILDERS WAREHOUSE:CRAIGHALL PARK | F42: AT SEASONAL COLOUR 12CM POT 850040171 | G42: -7 | H42: 7 | I42: -49 | J42: -679 | K42: {=_xlfn.LET(_xlpm.d,UPPER(TRIM(CLEAN(SUBSTITUTE(F42,CHAR(160)," ")))),_xlpm.keys,UPPER(TRIM(MAP!$B$1:$B$401)),_xlpm.vals,MAP!$A$1:$A$401,_xlpm.matchlen,IF(ISNUMBER(SEARCH(_xlpm.keys,_xlpm.d)),LEN(_xlpm.keys),0),_xlpm.best,MAX(_xlpm.matchlen),IF(_xlpm.best=0,"",INDEX(_xlpm.vals,MATCH(_xlpm.best,_xlpm.matchlen,0))))} -> 12CM COLOUR POT
B43: 46008 | C43: Credit Note | D43: 4401588383 | E43: BUILDERS WAREHOUSE:RUSTENBURG | F43: AT SEASONAL COLOUR 12CM POT 850040171 | G43: -6 | H43: 12.2 | I43: -73.2 | J43: -752.2 | K43: {=_xlfn.LET(_xlpm.d,UPPER(TRIM(CLEAN(SUBSTITUTE(F43,CHAR(160)," ")))),_xlpm.keys,UPPER(TRIM(MAP!$B$1:$B$401)),_xlpm.vals,MAP!$A$1:$A$401,_xlpm.matchlen,IF(ISNUMBER(SEARCH(_xlpm.keys,_xlpm.d)),LEN(_xlpm.keys),0),_xlpm.best,MAX(_xlpm.matchlen),IF(_xlpm.best=0,"",INDEX(_xlpm.vals,MATCH(_xlpm.best,_xlpm.matchlen,0))))} -> 12CM COLOUR POT
B44: 46009 | C44: Credit Note | D44: 4401588664 | E44: BUILDERS WAREHOUSE:ROBINDALE | F44: AT SEASONAL COLOUR 12CM POT 850040171 | G44: -18 | H44: 12.2 | I44: -219.6 | J44: -971.8 | K44: {=_xlfn.LET(_xlpm.d,UPPER(TRIM(CLEAN(SUBSTITUTE(F44,CHAR(160)," ")))),_xlpm.keys,UPPER(TRIM(MAP!$B$1:$B$401)),_xlpm.vals,MAP!$A$1:$A$401,_xlpm.matchlen,IF(ISNUMBER(SEARCH(_xlpm.keys,_xlpm.d)),LEN(_xlpm.keys),0),_xlpm.best,MAX(_xlpm.matchlen),IF(_xlpm.best=0,"",INDEX(_xlpm.vals,MATCH(_xlpm.best,_xlpm.matchlen,0))))} -> 12CM COLOUR POT
...

Sheet MAP
A1: 12CM COLOUR POT | B1: AT SEASONAL COLOUR 12CM POT | E1: SEEDLINGS
A2: 12CM COLOUR POT | B2: CELOSIA 12CM | E2: 15CM COLOUR POTS
A3: 12CM COLOUR POT | B3: AT HYPOESTES POT 12CM 850040155 | E3: 12CM COLOUR POT
A4: 12CM COLOUR POT | B4: AT IMPATIENS POT 12CM 850040109 | E4: 12CM HERB
A5: 12CM COLOUR POT | B5: COLOUR MAGIC 12CM | E5: PETUNIA HYBRIDS
A6: 12CM COLOUR POT | B6: PETUNIA 12CM | E6: PLANT TO PLATE
A7: 12CM PRIMROSE/OBCONICA | B7: PRIMROSE | E7: SIMPLY BEAUTIFUL
A8: 12CM COLOUR POT | B8: VINCA VICTORY GRAPE | E8: MID RANGE
A9: 12CM COLOUR POT | B9: FLOWER POT 12CM | E9: CALIBRACHOA
A10: 12CM HERB/VEG | B10: BASIL | E10: 20CM AERO BOWL
A11: 12CM HERB/VEG | B11: CHIVES | E11: 14CM SUCCULENTS
A12: 12CM HERB/VEG | B12: CORIANDER | E12: 25CM HANGING BASKET
... A24: 12CM HERB/VEG | B24: HERB L/STYLE | E24: CHILLI POT
A25: 12CM ORNAMENTAL CHILLI | B25: ORNAMENTAL CHILLI
A26: 12CM ORNAMENTAL CHILLI | B26: CHILLI ORNAMENTAL
A27: 12CM PATIO RANGE | B27: CALCEOLARIA | E27: LAWN PLUGS
A28: 12CM PATIO RANGE | B28: CINERARIA | E28: 12CM GRASS POTS
A29: 12CM PATIO RANGE | B29: CYCLAMEN | E29: 17CM GERANIUM
A30: 15CM COLOUR POTS | B30: PELARGONIUM
A31: 15CM COLOUR POTS | B31: ALYSSUM CLEAR CRYSTAL
A32: 15CM COLOUR POTS | B32: ANTIRRHINUM
A33: 15CM COLOUR POTS | B33: DIANTHUS
A34: 15CM COLOUR POTS | B34: CELOSIA DRACULA
A35: 15CM COLOUR POTS | B35: COLOUR MAGIC 15CM
A36: 15CM COLOUR POTS | B36: COLOUR MAGIC ALYSSUM
A37: 15CM COLOUR POTS | B37: COLOUR MAGIC BELLIS
A38: 15CM COLOUR POTS | B38: COLOUR MAGIC CALENDULA
A39: 15CM COLOUR POTS | B39: COLOUR MAGIC DIANTHUS
A40: 15CM COLOUR POTS | B40: COLOUR MAGIC GAZANIA
A41: 15CM COLOUR POTS | B41: COLOUR MAGIC GYPSOPHILLA
... A109: COLOUR PLUGS 48 | B109: COLOUR PLUGS 48
A110: SEEDLINGS | B110: 28884
A111: SEEDLINGS | B111: SEEDLING FLOWER 6 PACK
A112: SEEDLINGS | B112: SEEDLING VEGETABLE 6 PACK
A113: SEEDLINGS | B113: VEGETABLE SEEDLINGS 6 PACK
A114: 9CM SUCCULENTS | B114: COLOUR MAGIC 9CM
A115: 9CM SUCCULENTS | B115: ECHEVERIA SET OLIVER
A116: 9CM SUCCULENTS | B116: SUCCULENT 9CM
A117: ADVERTISING | B117: ADVERTISING
A118: BUILDERS REBATE | B118: BUILDERS REBATE
...

Sheet TABLE
A1: Years (Date) | B1: 2026
A2: Months (Date) | B2: Apr
A3: Date | B3: (All)
A5: Row Labels | B5: Sum of Quantity | C5: Percentage
A6: 12CM COLOUR POT | B6: -526 | C6: 0.030769231
A7: 12CM GRASS POTS | B7: -12 | C7: 0.00070195964
A8: 12CM HERB/VEG | B8: -477 | C8: 0.027902896
A9: 12CM PATIO RANGE | B9: -3 | C9: 0.00017548991
A10: 12CM PETUNIA HYBRIDS | B10: -242 | C10: 0.014156186
A11: 14CM SUCCULENTS | B11: -16 | C11: 0.00093594618
A12: 15CM ANGELONIA | B12: -27 | C12: 0.0015794092
A13: 15CM COLOUR POTS | B13: -2125 | C13: 0.12430535
A14: 20CM AERO BOWL | B14: -98 | C14: 0.0057326704
A15: 24 PACKS | B15: -38 | C15: 0.0022228722
A16: 25CM COLOUR POT | B16: -154 | C16: 0.009008482
A17: 25CM HANGING BASKET | B17: -198 | C17: 0.011582334
... A33: Grand Total | B33: -17095 | C33: 1
